Workbook

Sheet 3_statement_model
B2: NIKE, Inc. NYSE(NKE)
B3: 3-statement Model
B5: $ in millions | C5: Actuals | H5: Forecast
B6: Assumptions | C6: FY2022 | D6: FY2023 | E6: FY2024 | F6: FY2025 | G6: FY2026 | H6: FY2027 | I6: FY2028 | J6: FY2029 | K6: FY2030 | L6: FY2031
B8: Revenue Growth Rate (% Change) | C8: =C29 -> - | D8: =D29 -> 0.096488975 | E8: =E29 -> 0.0028310912 | F8: =F29 -> -0.098380125 | G8: =G29 -> 0.0019218726 | H8: =H29 -> -0.074264623 | I8: =I29 -> 0.02504138 | J8: =J29 -> 0.046739299 | ... L8: =L29 -> 0.046958726
B9: Cost of Goods Sold (% of Revenue) | C9: =C30/C28 -> 0.54016271 | D9: =D30/D28 -> 0.56475389 | E9: =E30/E28 -> 0.55439819 | F9: =F30/F28 -> 0.57265326 | G9: =G30/G28 -> 0.57086512 | H9: =H30/H28 -> 0.56056664 | I9: =I30/I28 -> 0.56056664 | J9: =J30/J28 -> 0.56056664 | ... L9: =L30/L28 -> 0.56056664
B10: Demand creation expense | C10: =C34/C28 -> 0.082423464 | D10: =D34/D28 -> 0.079270555 | E10: =E34/E28 -> 0.083427437 | F10: =F34/F28 -> 0.10125462 | G10: =G34/G28 -> 0.10246131 | H10: =Notes!C35 -> 0.10185796 | I10: =H10 -> 0.10185796 | J10: =I10 -> 0.10185796 | K10: =J10 -> 0.10185796 | L10: =K10 -> 0.10185796
B11: Operating overhead expense (% of Revenue) | C11: =C35/C28 -> 0.23451081 | D11: =D35/D28 -> 0.24048656 | E11: =E35/E28 -> 0.23930143 | F11: =F35/F28 -> 0.24615086 | G11: =G35/G28 -> 0.24483814 | H11: =Notes!C36 -> 0.2454945 | I11: =H11 -> 0.2454945 | J11: =I11 -> 0.2454945 | K11: =J11 -> 0.2454945 | L11: =K11 -> 0.2454945
B12: Depreciation & Amortization (% of Revenue) | C12: =C108/C28 -> 0.017983301 | D12: =D108/D28 -> 0.016771775 | E12: =E108/E28 -> 0.015497839 | F12: =F108/F28 -> 0.016735408 | G12: =G108/G28 -> 0.016099832 | H12: =Notes!C40 -> 0.016617631 | I12: =H12 -> 0.016617631 | J12: =I12 -> 0.016617631 | K12: =J12 -> 0.016617631 | L12: =K12 -> 0.016617631
B13: Net interest (% of debt) | C13: =C41/(C78+C79+C85) -> 0.02173913 | D13: =D41/(D78+D79+D85) -> -0.00067166685 | E13: =E41/(E78+E79+E85) -> -0.018071613 | F13: =F41/(F78+F79+F85) -> -0.013440523 | G13: =G41/(G78+G79+G85) -> -0.0062956434 | H13: =Notes!C57 -> 0.040621266 | I13: =H13 -> 0.040621266 | J13: =I13 -> 0.040621266 | K13: =J13 -> 0.040621266 | L13: =K13 -> 0.040621266
B14: Tax Rate (%of earning before tax) | C14: =C47 -> 0.090963765 | D14: =D47 -> 0.18238994 | E14: =E47 -> 0.14925373 | F14: =F47 -> 0.17142857 | G14: =G47 -> 0.20307692 | H14: =Notes!C53 -> 0.20307692 | I14: =H14 -> 0.20307692 | J14: =I14 -> 0.20307692 | K14: =J14 -> 0.20307692 | L14: =K14 -> 0.20307692
B15: Accounts Receivable (Days) | C15: =C66/C28*365 -> 36.468743 | D15: =D66/D28*365 -> 29.439737 | E15: =E66/E28*365 -> 31.460126 | F15: =F66/F28*365 -> 37.178626 | G15: =G66/G28*365 -> 46.657507 | H15: =Notes!C45 -> 41.918066 | I15: =H15 -> 41.918066 | J15: =I15 -> 41.918066 | K15: =J15 -> 41.918066 | L15: =K15 -> 41.918066
B16: Inventory (Days) | C16: =(C67/C30)*365 -> 121.80651 | D16: =(D67/D30)*365 -> 106.67969 | E16: =(E67/E30)*365 -> 96.380509 | F16: =(F67/F30)*365 -> 103.07647 | G16: =(G67/G30)*365 -> 103.36637 | H16: =Notes!C46 -> 103.22142 | I16: =H16 -> 103.22142 | J16: =I16 -> 103.22142 | K16: =J16 -> 103.22142 | L16: =K16 -> 103.22142
B17: Accounts Payables (Days) | C17: =C80/C30*365 -> 48.57794 | D17: =D80/D30*365 -> 36.115125 | E17: =E80/E30*365 -> 36.544864 | F17: =F80/F30*365 -> 47.88397 | G17: =G80/G30*365 -> 49.609242 | H17: =Notes!C47 -> 48.746606 | I17: =H17 -> 48.746606 | J17: =I17 -> 48.746606 | K17: =J17 -> 48.746606 | L17: =K17 -> 48.746606
B18: Capital Expenditure (% of revenue) | C18: =C158/C28 -> 0.016227788 | D18: =D158/D28 -> 0.018919499 | E18: =E158/E28 -> 0.015809353 | F18: =F158/F28 -> 0.0092854521 | G18: =G158/G28 -> 0.014742015 | H18: =Notes!C41 -> 0.014996822 | I18: =H18 -> 0.014996822 | J18: =I18 -> 0.014996822 | K18: =J18 -> 0.014996822 | L18: =K18 -> 0.014996822
B19: Debt Issuance(Repayment) | C19: =C127 -> 15 | D19: =D127 -> -504 | E19: =E127 -> 0 | F19: =F127 -> -1000 | G19: =G127 -> 0 | H19: =H127 -> -2000 | I19: =I127 -> 0 | J19: =J127 -> 0 | ... L19: =L127 -> 0
B20: Equity Issued (Repaid) | C20: =C128 -> -2863 | D20: =D128 -> -4829 | E20: =E128 -> -3583 | F20: =F128 -> -2434 | G20: =G128 -> 208 | H20: =H128 -> -750 | I20: =I128 -> -750 | J20: =J128 -> -750 | ... L20: =L128 -> -750
B21: Days in Period | C21: 365 | D21: 365 | E21: 365 | F21: 365 | G21: 365 | H21: 365 | I21: 365 | J21: 365 | K21: 365 | L21: 365
B25: $ in millions | C25: Actuals | H25: Forecast
B26: INCOME STATEMENT (consolidated) | C26: FY2022 | D26: FY2023 | E26: FY2024 | F26: FY2025 | G26: FY2026 | H26: FY2027 | I26: FY2028 | J26: FY2029 | K26: FY2030 | L26: FY2031
B28: Revenues | C28: 46710 | D28: 51217 | E28: 51362 | F28: 46309 | G28: 46398 | H28: =Revenue_Build!H16 -> 42952.27 | I28: =Revenue_Build!I16 -> 44027.854 | J28: =Revenue_Build!J16 -> 46085.685 | K28: =Revenue_Build!K16 -> 48244.808 | L28: =Revenue_Build!L16 -> 50510.323
B29: Revenue Growth | C29: - | D29: =(D28-C28)/C28 -> 0.096488975 | E29: =(E28-D28)/D28 -> 0.0028310912 | F29: =(F28-E28)/E28 -> -0.098380125 | G29: =(G28-F28)/F28 -> 0.0019218726 | H29: =(H28-G28)/G28 -> -0.074264623 | I29: =(I28-H28)/H28 -> 0.02504138 | J29: =(J28-I28)/I28 -> 0.046739299 | K29: =(K28-J28)/J28 -> 0.046850194 | L29: =(L28-K28)/K28 -> 0.046958726
B30: COGS | C30: 25231 | D30: 28925 | E30: 28475 | F30: 26519 | G30: 26487 | H30: =H28-H31 -> 24077.609 | I30: =I28-I31 -> 24680.546 | J30: =J28-J31 -> 25834.097 | K30: =K28-K31 -> 27044.43 | L30: =L28-L31 -> 28314.402
B31: Gross profit | C31: =C28-C30 -> 21479 | D31: =D28-D30 -> 22292 | E31: =E28-E30 -> 22887 | F31: =F28-F30 -> 19790 | G31: =G28-G30 -> 19911 | H31: =H28*H32 -> 18874.661 | I31: =I28*I32 -> 19347.308 | J31: =J28*J32 -> 20251.588 | K31: =K28*K32 -> 21200.378 | L31: =L28*L32 -> 22195.921
B32: Gross Profit Margin % | C32: =C31/C28 -> 0.45983729 | D32: =D31/D28 -> 0.43524611 | E32: =E31/E28 -> 0.44560181 | F32: =F31/F28 -> 0.42734674 | G32: =G31/G28 -> 0.42913488 | H32: =Notes!$C$34 -> 0.43943336 | I32: =H32 -> 0.43943336 | J32: =I32 -> 0.43943336 | K32: =J32 -> 0.43943336 | L32: =K32 -> 0.43943336
B33: Expenses
B34: Demand creation expense | C34: 3850 | D34: 4060 | E34: 4285 | F34: 4689 | G34: 4754 | H34: =H28*H10 -> 4375.0308 | I34: =I28*I10 -> 4484.5876 | J34: =J28*J10 -> 4694.1941 | K34: =K28*K10 -> 4914.118 | L34: =L28*L10 -> 5144.8787
B35: Operating overhead expense | C35: 10954 | D35: 12317 | E35: 12291 | F35: 11399 | G35: 11360 | H35: =H28*H11 -> 10544.546 | I35: =I28*I11 -> 10808.596 | J35: =J28*J11 -> 11313.782 | K35: =K28*K11 -> 11843.835 | L35: =L28*L11 -> 12400.006
B36: Total selling and administrative expense | C36: =C34+C35 -> 14804 | D36: =D34+D35 -> 16377 | E36: =E34+E35 -> 16576 | F36: =F34+F35 -> 16088 | G36: =G34+G35 -> 16114 | H36: =H34+H35 -> 14919.577 | I36: =I34+I35 -> 15293.184 | J36: =J34+J35 -> 16007.976 | ... L36: =L34+L35 -> 17544.885
B37: S&G expense % of Sales | C37: =C36/C28 -> 0.31693428 | D37: =D36/D28 -> 0.31975711 | E37: =E36/E28 -> 0.32272887 | F37: =F36/F28 -> 0.34740547 | G37: =G36/G28 -> 0.34729945 | H37: =H36/H28 -> 0.34735246 | I37: =I36/I28 -> 0.34735246 | J37: =J36/J28 -> 0.34735246 | ... L37: =L36/L28 -> 0.34735246
B39: Operating Income (EBIT) | C39: =C31-C36 -> 6675 | D39: =D31-D36 -> 5915 | E39: =E31-E36 -> 6311 | F39: =F31-F36 -> 3702 | G39: =G31-G36 -> 3797 | H39: =H31-H36 -> 3955.0838 | I39: =I31-I36 -> 4054.1245 | J39: =J31-J36 -> 4243.6115 | ... L39: =L31-L36 -> 4651.0361
B40: EBIT Margin (%) | C40: =C39/C28 -> 0.14290302 | D40: =D39/D28 -> 0.115489 | E40: =E39/E28 -> 0.12287294 | F40: =F39/F28 -> 0.079941264 | G40: =G39/G28 -> 0.081835424 | H40: =H39/H28 -> 0.092080902 | I40: =I39/I28 -> 0.092080902 | J40: =J39/J28 -> 0.092080902 | ... L40: =L39/L28 -> 0.092080902
B41: Interest expense (income), net | C41: 205 | D41: -6 | E41: -161 | F41: -107 | G41: -50 | H41: =H166 -> -38.465902 | I41: =I166 -> -107.48636 | J41: =J166 -> -135.77839 | K41: =K166 -> -167.11696 | L41: =L166 -> -206.77191
B42: Other (income) expense, net | C42: -181 | D42: -280 | E42: -228 | F42: -76 | G42: -53 | H42: =Notes!$C$37 -> 0 | I42: =H42 -> 0 | J42: =I42 -> 0 | K42: =J42 -> 0 | L42: =K42 -> 0
B44: Income before income taxes | C44: =C31-C36-C41-C42 -> 6651 | D44: =D31-D36-D41-D42 -> 6201 | E44: =E31-E36-E41-E42 -> 6700 | F44: =F31-F36-F41-F42 -> 3885 | G44: =G31-G36-G41-G42 -> 3900 | H44: =H31-H36-H41-H42 -> 3993.5497 | I44: =I31-I36-I41-I42 -> 4161.6109 | J44: =J31-J36-J41-J42 -> 4379.3899 | ... L44: =L31-L36-L41-L42 -> 4857.808
B46: Income tax expense | C46: 605 | D46: 1131 | E46: 1000 | F46: 666 | G46: 792 | H46: =H44*H47 -> 810.99778 | I46: =I44*I47 -> 845.12714 | J46: =J44*J47 -> 889.35302 | K46: =K44*K47 -> 936.0917 | L46: =L44*L47 -> 986.50871
B47: Effective Tax Rate | C47: =C46/C44 -> 0.090963765 | D47: =D46/D44 -> 0.18238994 | E47: =E46/E44 -> 0.14925373 | F47: =F46/F44 -> 0.17142857 | G47: =G46/G44 -> 0.20307692 | H47: =H14 -> 0.20307692 | I47: =I14 -> 0.20307692 | J47: =J14 -> 0.20307692 | K47: =K14 -> 0.20307692 | L47: =L14 -> 0.20307692
B49: Net Income | C49: =C44-C46 -> 6046 | D49: =D44-D46 -> 5070 | E49: =E44-E46 -> 5700 | F49: =F44-F46 -> 3219 | G49: =G44-G46 -> 3108 | H49: =H44-H46 -> 3182.5519 | I49: =I44-I46 -> 3316.4838 | J49: =J44-J46 -> 3490.0368 | ... L49: =L44-L46 -> 3871.2993
B50: Net Income Margin | C50: =C49/C28 -> 0.12943695 | D50: =D49/D28 -> 0.09899057 | E50: =E49/E28 -> 0.11097699 | F50: =F49/F28 -> 0.069511326 | G50: =G49/G28 -> 0.066985646 | H50: =H49/H28 -> 0.07409508 | I50: =I49/I28 -> 0.075326945 | J50: =J49/J28 -> 0.075729304 | ... L50: =L49/L28 -> 0.076643725
B52: Earnings per share and shares
...

Sheet Revenue_Build
B2: NIKE, Inc. NYSE(NKE)
B3: Revenue_Build
B5: $ in millions | C5: Actuals | H5: Forecast
B6: Revenue | C6: FY2022 | D6: FY2023 | E6: FY2024 | F6: FY2025 | G6: FY2026 | H6: FY2027 | I6: FY2028 | J6: FY2029 | K6: FY2030 | L6: FY2031
B8: North America | C8: 18353 | D8: 21608 | E8: 21396 | F8: 19572 | G8: 20511 | H8: =G8*(1+Notes!C11) -> 20511 | I8: =H8*(1+Notes!C17) -> 21331.44 | J8: =I8*(1+Notes!C23) -> 22398.012 | K8: =J8*(1+Notes!C23) -> 23517.913 | L8: =K8*(1+Notes!C23) -> 24693.808
B9: Europe, Middle East & Africa | C9: 12479 | D9: 13418 | E9: 13607 | F9: 12257 | G9: 12572 | H9: =G9*(1+Notes!C12) -> 11314.8 | I9: =H9*(1+Notes!C18) -> 11654.244 | J9: =I9*(1+Notes!C24) -> 12178.685 | K9: =J9*(1+Notes!C24) -> 12726.726 | L9: =K9*(1+Notes!C24) -> 13299.428
B10: Greater China | C10: 7547 | D10: 7248 | E10: 7545 | F10: 6586 | G10: 5847 | H10: =G10*(1+Notes!C13) -> 4385.25 | I10: =H10*(1+Notes!C19) -> 4165.9875 | J10: =I10*(1+Notes!C25) -> 4270.1372 | K10: =J10*(1+Notes!C25) -> 4376.8906 | L10: =K10*(1+Notes!C25) -> 4486.3129
B11: Asia Pacific & Latin America | C11: 5955 | D11: 6431 | E11: 6729 | F11: 6251 | G11: 6243 | H11: =G11*(1+Notes!C14) -> 5868.42 | I11: =H11*(1+Notes!C20) -> 6044.4726 | J11: =I11*(1+Notes!C26) -> 6407.141 | K11: =J11*(1+Notes!C26) -> 6791.5694 | L11: =K11*(1+Notes!C26) -> 7199.0636
B12: Global Brand Divisions | C12: 102 | D12: 58 | E12: 45 | F12: 48 | G12: 49 | H12: =G12*(1+Notes!$C$29) -> 49 | I12: =H12*(1+Notes!$C$29) -> 49 | J12: =I12*(1+Notes!$C$29) -> 49 | K12: =J12*(1+Notes!$C$29) -> 49 | L12: =K12*(1+Notes!$C$29) -> 49
B13: NIKE Brand revenue | C13: =SUM(C8:C12) -> 44436 | D13: =SUM(D8:D12) -> 48763 | E13: =SUM(E8:E12) -> 49322 | F13: =SUM(F8:F12) -> 44714 | G13: =SUM(G8:G12) -> 45222 | H13: =SUM(H8:H12) -> 42128.47 | I13: =SUM(I8:I12) -> 43245.144 | J13: =SUM(J8:J12) -> 45302.975 | ... L13: =SUM(L8:L12) -> 49727.613
B14: Converse | C14: 2346 | D14: 2427 | E14: 2082 | F14: 1692 | G14: 1174 | H14: =G14*(1+Notes!C$15) -> 821.8 | I14: =H14*(1+Notes!C21) -> 780.71 | J14: =I14*(1+Notes!C27) -> 780.71 | K14: =J14*(1+Notes!C27) -> 780.71 | L14: =K14*(1+Notes!C27) -> 780.71
B15: Corporate | C15: -72 | D15: 27 | E15: -42 | F15: -97 | G15: 2 | H15: =G15*(1+Notes!$C$29) -> 2 | I15: =H15*(1+Notes!$C$29) -> 2 | J15: =I15*(1+Notes!$C$29) -> 2 | K15: =J15*(1+Notes!$C$29) -> 2 | L15: =K15*(1+Notes!$C$29) -> 2
B16: TOTAL NIKE, INC. REVENUE | C16: =C13+C14+C15 -> 46710 | D16: =D13+D14+D15 -> 51217 | E16: =E13+E14+E15 -> 51362 | F16: =F13+F14+F15 -> 46309 | G16: =G13+G14+G15 -> 46398 | H16: =H13+H14+H15 -> 42952.27 | I16: =I13+I14+I15 -> 44027.854 | J16: =J13+J14+J15 -> 46085.685 | ... L16: =L13+L14+L15 -> 50510.323
B17: Revenue growth | C17: - | D17: =D16/C16-1 -> 0.096488975 | E17: =E16/D16-1 -> 0.0028310912 | F17: =F16/E16-1 -> -0.098380125 | G17: =G16/F16-1 -> 0.0019218726 | H17: =H16/G16-1 -> -0.074264623 | I17: =I16/H16-1 -> 0.02504138 | J17: =J16/I16-1 -> 0.046739299 | K17: =K16/J16-1 -> 0.046850194 | L17: =L16/K16-1 -> 0.046958726
B18: Check: 3_statement_model revenue (must be 0) | C18: =C16-'3_statement_model'!C28 -> 0 | D18: =D16-'3_statement_model'!D28 -> 0 | E18: =E16-'3_statement_model'!E28 -> 0 | F18: =F16-'3_statement_model'!F28 -> 0 | G18: =G16-'3_statement_model'!G28 -> 0
B20: YoY growth by segment
B21: North America | C21: - | D21: =(D8/C8)-1 -> 0.1773552 | E21: =(E8/D8)-1 -> -0.009811181 | F21: =(F8/E8)-1 -> -0.085249579 | G21: =(G8/F8)-1 -> 0.047976701 | H21: =H8/G8-1 -> 0 | I21: =I8/H8-1 -> 0.04 | J21: =J8/I8-1 -> 0.05 | K21: =K8/J8-1 -> 0.05 | L21: =L8/K8-1 -> 0.05
B22: EMEA | C22: - | D22: =D9/C9-1 -> 0.075246414 | E22: =E9/D9-1 -> 0.014085557 | F22: =F9/E9-1 -> -0.09921364 | G22: =G9/F9-1 -> 0.0256996 | H22: =H9/G9-1 -> -0.1 | I22: =I9/H9-1 -> 0.03 | J22: =J9/I9-1 -> 0.045 | K22: =K9/J9-1 -> 0.045 | L22: =L9/K9-1 -> 0.045
B23: Greater China | C23: - | D23: =D10/C10-1 -> -0.039618391 | E23: =E10/D10-1 -> 0.040976821 | F23: =F10/E10-1 -> -0.12710404 | G23: =G10/F10-1 -> -0.11220771 | H23: =H10/G10-1 -> -0.25 | I23: =I10/H10-1 -> -0.05 | J23: =J10/I10-1 -> 0.025 | K23: =K10/J10-1 -> 0.025 | L23: =L10/K10-1 -> 0.025
B24: APLA | C24: - | D24: =D11/C11-1 -> 0.07993283 | E24: =E11/D11-1 -> 0.04633805 | F24: =F11/E11-1 -> -0.071035815 | G24: =G11/F11-1 -> -0.0012797952 | H24: =H11/G11-1 -> -0.06 | I24: =I11/H11-1 -> 0.03 | J24: =J11/I11-1 -> 0.06 | K24: =K11/J11-1 -> 0.06 | L24: =L11/K11-1 -> 0.06
B25: Converse | C25: - | D25: =D14/C14-1 -> 0.034526854 | E25: =E14/D14-1 -> -0.1421508 | F25: =F14/E14-1 -> -0.18731988 | G25: =G14/F14-1 -> -0.30614657 | H25: =H14/G14-1 -> -0.3 | I25: =I14/H14-1 -> -0.05 | J25: =J14/I14-1 -> 0 | K25: =K14/J14-1 -> 0 | L25: =L14/K14-1 -> 0
B27: % of Total Revenue
B28: North America | C28: =C8/C$16 -> 0.39291372 | D28: =D8/D$16 -> 0.42189117 | E28: =E8/E$16 -> 0.41657256 | F28: =F8/F$16 -> 0.42263923 | G28: =G8/G$16 -> 0.44206647 | H28: =H8/H$16 -> 0.47753006 | I28: =I8/I$16 -> 0.48449874 | J28: =J8/J$16 -> 0.48600801 | ... L28: =L8/L$16 -> 0.48888636
B29: EMEA | C29: =C9/C$16 -> 0.26715907 | D29: =D9/D$16 -> 0.26198333 | E29: =E9/E$16 -> 0.26492348 | F29: =F9/F$16 -> 0.26467857 | G29: =G9/G$16 -> 0.27095996 | H29: =H9/H$16 -> 0.26342729 | I29: =I9/I$16 -> 0.26470161 | J29: =J9/J$16 -> 0.26426178 | ... L29: =L9/L$16 -> 0.2633012
B30: Greater China | C30: =C10/C$16 -> 0.1615714 | D30: =D10/D$16 -> 0.14151551 | E30: =E10/E$16 -> 0.14689849 | F30: =F10/F$16 -> 0.14221858 | G30: =G10/G$16 -> 0.12601836 | H30: =H10/H$16 -> 0.10209588 | I30: =I10/I$16 -> 0.094621634 | J30: =J10/J$16 -> 0.092656476 | ... L30: =L10/L$16 -> 0.088819722
B31: APLA | C31: =C11/C$16 -> 0.12748876 | D31: =D11/D$16 -> 0.12556378 | E31: =E11/E$16 -> 0.13101125 | F31: =F11/F$16 -> 0.13498456 | G31: =G11/G$16 -> 0.13455321 | H31: =H11/H$16 -> 0.13662654 | I31: =I11/I$16 -> 0.13728747 | J31: =J11/J$16 -> 0.13902671 | ... L31: =L11/L$16 -> 0.14252658
B32: Converse | C32: =C14/C$16 -> 0.050224791 | D32: =D14/D$16 -> 0.04738661 | E32: =E14/E$16 -> 0.040535805 | F32: =F14/F$16 -> 0.036537174 | G32: =G14/G$16 -> 0.025302815 | H32: =H14/H16 -> 0.019132865 | I32: =I14/I16 -> 0.017732184 | J32: =J14/J16 -> 0.016940401 | K32: =K14/K16 -> 0.016182259 | L32: =L14/L16 -> 0.015456444
B34: NIKE Brand revenue by product (10-K revenue note)
B35: Footwear | C35: 29143 | D35: 33135 | E35: 33427 | F35: 29510 | G35: 29525
B36: Apparel | C36: 13567 | D36: 13843 | E36: 13775 | F36: 12965 | G36: 13449
B37: Equipment | C37: 1624 | D37: 1727 | E37: 2075 | F37: 2191 | G37: 2199
B38: Global Brand Divisions | C38: =C12 -> 102 | D38: =D12 -> 58 | E38: =E12 -> 45 | F38: =F12 -> 48 | G38: =G12 -> 49
B39: NIKE Brand revenue (product view) | C39: =SUM(C35:C38) -> 44436 | D39: =SUM(D35:D38) -> 48763 | E39: =SUM(E35:E38) -> 49322 | F39: =SUM(F35:F38) -> 44714 | G39: =SUM(G35:G38) -> 45222
B40: Check: | C40: =C39-C13 -> 0 | D40: =D39-D13 -> 0 | E40: =E39-E13 -> 0 | F40: =F39-F13 -> 0 | G40: =G39-G13 -> 0
B42: Source: Nike Form 10-K, Business Today, NIKE FY2027 Q1 results

Sheet Notes
B2: NIKE, Inc. NYSE(NKE)
B3: 3-statement Model
B5: Active Scenario: 1=Bear, 2- Base, 3- Bull | C5: 2 | D5: =CHOOSE(C5,"Bear","Base","Bull") -> Base
B7: $ in millions
B8: Parameter | C8: Active | D8: Unit | E8: Notes | G8: Bear | H8: Base | I8: Bull
B10: Revenue Growth & Mix
B11: North America growth – FY2027 | C11: =CHOOSE($C$5,G11,H11,I11) -> 0 | D11: %/year | G11: -0.03 | H11: 0 | I11: 0.03
B12: Europe, Middle East & Africa growth – FY2027 | C12: =CHOOSE($C$5,G12,H12,I12) -> -0.1 | D12: %/year | G12: -0.13 | H12: -0.1 | I12: -0.07
B13: Greater China growth – FY2027 | C13: =CHOOSE($C$5,G13,H13,I13) -> -0.25 | D13: %/year | G13: -0.28 | H13: -0.25 | I13: -0.22
B14: Asia Pacific & Latin America growth – FY2027 | C14: =CHOOSE($C$5,G14,H14,I14) -> -0.06 | D14: %/year | G14: -0.09 | H14: -0.06 | I14: -0.03
B15: Converse growth – FY2027 | C15: =CHOOSE($C$5,G15,H15,I15) -> -0.3 | D15: %/year | G15: -0.33 | H15: -0.3 | I15: -0.27
B17: North America growth – FY2028 | C17: =CHOOSE($C$5,G17,H17,I17) -> 0.04 | D17: %/year | G17: 0.02 | H17: 0.04 | I17: 0.06
B18: Europe, Middle East & Africa growth – FY2028 | C18: =CHOOSE($C$5,G18,H18,I18) -> 0.03 | D18: %/year | G18: 0.01 | H18: 0.03 | I18: 0.05
B19: Greater China growth – FY2028 | C19: =CHOOSE($C$5,G19,H19,I19) -> -0.05 | D19: %/year | G19: -0.07 | H19: -0.05 | I19: -0.03
B20: Asia Pacific & Latin America growth – FY2028 | C20: =CHOOSE($C$5,G20,H20,I20) -> 0.03 | D20: %/year | G20: 0.01 | H20: 0.03 | I20: 0.05
B21: Converse growth – FY2028 | C21: =CHOOSE($C$5,G21,H21,I21) -> -0.05 | D21: %/year | G21: -0.07 | H21: -0.05 | I21: -0.03
B23: North America growth – FY2029-31 | C23: =CHOOSE($C$5,G23,H23,I23) -> 0.05 | D23: %/year | G23: 0.03 | H23: 0.05 | I23: 0.07
B24: Europe, Middle East & Africa growth – FY2029-31 | C24: =CHOOSE($C$5,G24,H24,I24) -> 0.045 | D24: %/year | G24: 0.025 | H24: 0.045 | I24: 0.065
... B27: Converse growth – FY2029-31 | C27: =CHOOSE($C$5,G27,H27,I27) -> 0 | D27: %/year | G27: -0.02 | H27: 0 | I27: 0.02
B29: Global Brand Divisions + Corporate revenue | C29: 0 | D29: %/year | G29: - | H29: - | I29: -
B30: Total revenue growth- FY2027 | C30: =Revenue_Build!H17 -> -0.074264623
B32: Margins & Operating Expenses
B34: Gross Margin | C34: =CHOOSE($C$5,G34,H34,I34) -> 0.43943336 | D34: % | E34: 5-yr average (FY22–26) | G34: =H34-0.5% -> 0.43443336 | H34: =AVERAGE('3_statement_model'!C32:G32) -> 0.43943336 | I34: =H34+0.5% -> 0.44443336
B35: Demand creation expense % of revenue | C35: =AVERAGE('3_statement_model'!F10:G10) -> 0.10185796 | D35: % of revenue | E35: FY25-26 average
B36: Operating overhead expense % of revenue | C36: =CHOOSE($C$5,G36,H36,I36) -> 0.2454945 | D36: % of revenue | E36: FY25-26 avg | G36: =H36+0.5% -> 0.2504945 | H36: =AVERAGE('3_statement_model'!G35/'3_statement_model'!G28,'3_statement_model'!F35/'3_statement_model'!F28) -> 0.2454945 | I36: =H36-0.5% -> 0.2404945
B37: Other (income) expense, net | C37: 0
B39: Depreciation, Capex & Stock Compensation
B40: D&A % of revenue | C40: =AVERAGE('3_statement_model'!C12:G12) -> 0.016617631 | D40: % of revenue | E40: 5-yr average
B41: Capex % of revenue | C41: =AVERAGE('3_statement_model'!C18:G18) -> 0.014996822 | D41: % of revenue | E41: 5-yr average
B42: Stock-based compensation % of revenue | C42: 0.015 | D42: % of revenue | E42: 5-yr average
B44: Working Capital
B45: Receivable days (DSO = AR / revenue x 365) | C45: =AVERAGE('3_statement_model'!F66/'3_statement_model'!F28*365,'3_statement_model'!G66/'3_statement_model'!G28*365) -> 41.918066 | D45: days | E45: FY25-26 average
B46: Inventory days (DIO = inventory / COGS x 365) | C46: =CHOOSE($C$5,G46,H46,I46) -> 103.22142 | D46: days | E46: Bear FY22-23 average, Bull FY24 | G46: =AVERAGE('3_statement_model'!C67/'3_statement_model'!C30*365,'3_statement_model'!D67/'3_statement_model'!D30*365) -> 114.2431 | H46: =AVERAGE('3_statement_model'!F67/'3_statement_model'!F30*365,'3_statement_model'!G67/'3_statement_model'!G30*365) -> 103.22142 | I46: ='3_statement_model'!E67/'3_statement_model'!E30*365 -> 96.380509
B47: Payable days (DPO = AP / COGS x 365) | C47: =AVERAGE('3_statement_model'!F80/'3_statement_model'!F30*365,'3_statement_model'!G80/'3_statement_model'!G30*365) -> 48.746606 | D47: days | E47: FY25-26 average
B48: Prepaid & other current assets % of revenue | C48: =AVERAGE('3_statement_model'!F68/'3_statement_model'!F28,'3_statement_model'!G68/'3_statement_model'!G28) -> 0.044752504 | D48: % of revenue | E48: FY25-26 average
B49: Accrued liabilities % of revenue | C49: =AVERAGE('3_statement_model'!F82/'3_statement_model'!F28,'3_statement_model'!G82/'3_statement_model'!G28) -> 0.12952465 | D49: % of revenue | E49: FY25-26 average
B50: Income taxes payable % of tax expense | C50: =MEDIAN('3_statement_model'!C83/'3_statement_model'!C46,'3_statement_model'!D83/'3_statement_model'!D46,'3_statement_model'!E83/'3_statement_model'!E46,'3_statement_model'!F83/'3_statement_model'!F46,'3_statement_model'!G83/'3_statement_model'!G46) -> 0.4760101 | D50: % of tax | E50: 5-yr median
B52: Tax
B53: Effective tax rate | C53: =CHOOSE($C$5,G53,H53,I53) -> 0.20307692 | D53: % | E53: Base FY26, Bear-Management Guidance, Bull 5-yr Avg | G53: 0.25 | H53: ='3_statement_model'!G47 -> 0.20307692 | I53: =AVERAGE('3_statement_model'!C47:G47) -> 0.15942259
B55: Debt & Interest
...
